Workbook
Name series: All_Streaming_Shows!$A$1:$I$200
Name seriesH: 'For Hlookup'!$A$1:$Z$9
Name Slicer_Content_Rating: #N/A
Name Slicer_Genre2: #N/A
Name Slicer_Streaming_Platform2: #N/A

Sheet All_Streaming_Shows
A1: Series Title | B1: Year Released | C1: Content Rating | D1: IMDB Rating | E1: R Rating | F1: Genre | G1: Description | H1: No of Seasons | I1: Streaming Platform
A2: Breaking Bad | B2: 2008 | C2: 18+ | D2: 9.5 | E2: 100 | F2: Crime,Drama | G2: When Walter White, a New Mexico chemistry teacher, is diagnosed with Stage III cancer and given a prognosis of only two years left to live. He becomes filled with a sense of fearlessness and an unrelenting desire to secure his family's financial future at any cost as he enters the dangerous world of drugs and crime.Breaking Bad featuring Bryan Cranston and Aaron Paul has one or more episodes streaming with subscription on Netflix, available for purchase on iTunes, available for purchase on Google Play, and 3 others. It's a crime and drama show with 62 episodes over 5 seasons. Breaking Bad is no longer running and has no plans to air new episodes or seasons. It has a very high IMDb audience rating of 9.5 (1,391,409 votes) and was very well received by critics. | H2: 5Seasons | I2: Netflix
A3: Game of Thrones | B3: 2011 | C3: 18+ | D3: 9.3 | E3: 99 | F3: Action & Adventure,Drama | G3: Seven noble families fight for control of the mythical land of Westeros. Friction between the houses leads to full-scale war. All while a very ancient evil awakens in the farthest north. Amidst the war, a neglected military order of misfits, the Night's Watch, is all that stands between the realms of men and icy horrors beyond.Game of Thrones featuring Emilia Clarke and Lena Headey has one or more episodes streaming with subscription on HBO MAX, streaming on HBO, available for purchase on iTunes, and 5 others. It's an action & adventure and drama show with 74 episodes over 8 seasons. Game of Thrones is no longer running and has no plans to air new episodes or seasons. It has a very high IMDb audience rating of 9.3 (1,704,731 votes) and was very well received by critics. | H3: 8Seasons | I3: HBO MAX,HBO
A4: Rick and Morty | B4: 2013 | C4: 18+ | D4: 9.2 | E4: 97 | F4: Animation,Comedy | G4: Rick is a mentally-unbalanced but scientifically-gifted old man who has recently reconnected with his family. He spends most of his time involving his young grandson Morty in dangerous, outlandish adventures throughout space and alternate universes. Compounded with Morty's already unstable family life, these events cause Morty much distress at home and school.Rick and Morty featuring Justin Roiland and Chris Parnell has one or more episodes streaming with subscription on HBO MAX, streaming with subscription on Hulu, streaming via tv everywhere with Adult Swim (Via Cable/Satellite Provider), and 8 others. It's an action & adventure and animation show with 42 episodes over 4 seasons. Rick and Morty is still airing with no announced date for the next episode or season. It has a very high IMDb audience rating of 9.2 (354,057 votes) and was very well received by critics. | H4: 4Seasons | I4: Free Services,HBO MAX,Hulu
A5: Stranger Things | B5: 2016 | C5: 16+ | D5: 8.8 | E5: 96 | F5: Drama,Fantasy | G5: When a young boy vanishes, a small town uncovers a mystery involving secret experiments, terrifying supernatural forces, and one strange little girl.Stranger Things featuring Winona Ryder and David Harbour has one or more episodes streaming with subscription on Netflix. It's an action & adventure and drama show with 25 episodes over 3 seasons. Stranger Things is still airing with no announced date for the next episode or season. It has a high IMDb audience rating of 8.8 (766,806 votes) and was very well received by critics. | H5: 3Seasons | I5: Netflix
A6: The Boys | B6: 2019 | C6: 18+ | D6: 8.7 | E6: 95 | F6: Action & Adventure,Comedy | G6: A group of vigilantes known informally as “The Boys” set out to take down corrupt superheroes with no more than blue-collar grit and a willingness to fight dirty.The Boys featuring Karl Urban and Jack Quaid has one or more episodes streaming with subscription on Prime Video, and available for purchase on VUDU. It's an action & adventure and comedy show with 12 episodes over 2 seasons. The Boys has a new episode airing on September 17th, 2020 (PDT). It has a high IMDb audience rating of 8.7 (170,705 votes) and was very well received by critics. | H6: 2Seasons | I6: Prime Video
A7: Dark | B7: 2017 | C7: 16+ | D7: 8.8 | E7: 95 | F7: Crime,Drama | G7: A missing child causes four families to help each other for answers. What they could not imagine is that this mystery would be connected to innumerable other secrets of the small town.Dark has one or more episodes streaming with subscription on Netflix. It's a crime and drama show with 26 episodes over 3 seasons. Dark is no longer running and has no plans to air new episodes or seasons. It has a high IMDb audience rating of 8.8 (249,219 votes) and was very well received by critics. | H7: 3Seasons | I7: Netflix
A8: Chernobyl | B8: 2019 | C8: 18+ | D8: 9.4 | E8: 95 | F8: Drama,History | G8: The true story of one of the worst man-made catastrophes in history: the catastrophic nuclear accident at Chernobyl. A tale of the brave men and women who sacrificed to save Europe from unimaginable disaster.Chernobyl featuring Jared Harris and Stellan Skarsgård has one or more episodes streaming with subscription on HBO MAX, streaming on HBO, available for purchase on Google Play, and 2 others. It's a drama and history show with 5 episodes over 1 season. Chernobyl is no longer running and has no plans to air new episodes or seasons. It has a very high IMDb audience rating of 9.4 (494,136 votes) and was very well received by critics. | H8: 1Season | I8: HBO MAX,HBO
A9: Sherlock | B9: 2010 | C9: 16+ | D9: 9.1 | E9: 94 | F9: Action & Adventure,Crime | G9: A modern update finds the famous sleuth and his doctor partner solving crime in 21st century London.Sherlock featuring Benedict Cumberbatch and Martin Freeman has one or more episodes streaming with subscription on Netflix, available for purchase on iTunes, available for purchase on Google Play, and 3 others. It's an action & adventure and crime show with 13 episodes over 4 seasons. Sherlock is no longer running and has no plans to air new episodes or seasons. It has a very high IMDb audience rating of 9.1 (778,486 votes) and was well received by critics. | H9: 4Seasons | I9: Netflix
A10: Fargo | B10: 2014 | C10: 18+ | D10: 8.9 | E10: 94 | F10: Crime,Drama | G10: A close-knit anthology series dealing with stories involving malice, violence and murder based in and around Minnesota.Fargo featuring Ewan McGregor and Michael Stuhlbarg has one or more episodes streaming with subscription on Hulu, available for purchase on iTunes, available for purchase on Google Play, and 3 others. It's a comedy and crime show with 30 episodes over 3 seasons. Fargo is still airing with no announced date for the next episode or season. It has a high IMDb audience rating of 8.9 (309,584 votes) and was very well received by critics. | H10: 3Seasons | I10: Hulu
A11: Avatar: The Last Airbender | B11: 2005 | C11: 7+ | D11: 9.2 | E11: 94 | F11: Action & Adventure,Animation | G11: In a war-torn world of elemental magic, a young boy reawakens to undertake a dangerous mystic quest to fulfill his destiny as the Avatar, and bring peace to the world.Avatar: The Last Airbender featuring Olivia Hack and Jennie Kwan has one or more episodes streaming with subscription on Netflix, streaming on CBS All Access, streaming with subscription on Hoopla, and 6 others. It's an action & adventure and animation show with 66 episodes over 3 seasons. Avatar: The Last Airbender is no longer running and has no plans to air new episodes or seasons. It has a very high IMDb audience rating of 9.2 (232,305 votes) and was very well received by critics. | H11: 3Seasons | I11: Netflix,CBS All Access,Hoopla
A12: Friends | B12: 1994 | C12: 16+ | D12: 8.9 | E12: 94 | F12: Comedy,Romance | G12: The misadventures of a group of friends as they navigate the pitfalls of work, life and love in Manhattan.Friends featuring Matthew Perry and Matt LeBlanc has one or more episodes streaming with subscription on HBO MAX, streaming with subscription on Hulu, streaming via tv everywhere with TBS, and 6 others. It's a comedy and drama show with 238 episodes over 10 seasons. Friends is no longer running and has no plans to air new episodes or seasons. It has a high IMDb audience rating of 8.9 (785,332 votes) and was well received by critics. | H12: 10Seasons | I12: HBO MAX,Hulu,TBS
A13: The Office | B13: 2005 | C13: 16+ | D13: 8.9 | E13: 93 | F13: Comedy,2005 | G13: The everyday lives of office employees in the Scranton, Pennsylvania branch of the fictional Dunder Mifflin Paper Company.The Office featuring Rainn Wilson and Jenna Fischer has one or more episodes streaming with subscription on Netflix, streaming via tv everywhere with Comedy Central (Via Cable/Satellite Provider), streaming with subscription on fuboTV, and 3 others. It's a comedy show with 224 episodes over 9 seasons. The Office is no longer running and has no plans to air new episodes or seasons. It has a high IMDb audience rating of 8.9 (378,896 votes) and was well received by critics. | H13: 9Seasons | I13: Netflix,Comedy Central,fuboTV
... A122: Planet Earth II | B122: 2016 | C122: all | D122: 9.5 | E122: 86 | F122: Documentary,2016 | G122: David Attenborough presents a documentary series exploring how animals meet the challenges of surviving in the most iconic habitats on earth.Planet Earth II featuring David Attenborough has one or more episodes streaming via tv everywhere with BBC America (Via Cable/Satellite Provider), available for purchase on iTunes, available for purchase on Google Play, and 3 others. It's a documentary show with 7 episodes over 1 season. Planet Earth II is no longer running and has no plans to air new episodes or seasons. It has a very high IMDb audience rating of 9.5 (91,536 votes) and was very well received by critics. | H122: 1Season | I122: BBC America
A123: 24 | B123: 2001 | C123: 16+ | D123: 8.3 | E123: 86 | F123: Action & Adventure,Drama | G123: 24 is an American television series produced for the Fox network and syndicated worldwide, starring Kiefer Sutherland as Counter Terrorist Unit agent Jack Bauer. Each 24-episode season covers 24 hours in the life of Bauer, using the real time method of narration.24 featuring Kiefer Sutherland and Mary Lynn Rajskub has one or more episodes streaming with subscription on Hulu, available for purchase on iTunes, available for purchase on Google Play, and 4 others. It's an action & adventure and crime show with 205 episodes over 9 seasons. 24 is no longer running and has no plans to air new episodes or seasons. It has a high IMDb audience rating of 8.3 (168,700 votes) and was well received by critics. | H123: 9 Seasons | I123: Hulu
A124: What We Do in the Shadows | B124: 2019 | C124: 18+ | D124: 8.5 | E124: 85 | F124: Comedy,Fantasy | G124: A documentary-style look into the daily (or rather, nightly) lives of three vampires in Staten Island who have “lived” together for hundreds and hundreds of years.What We Do in the Shadows featuring Kayvan Novak and Matt Berry has one or more episodes streaming with subscription on Hulu, available for purchase on Google Play, available for purchase on VUDU, and 1 other. It's a comedy and fantasy show with 20 episodes over 2 seasons. What We Do in the Shadows is still airing with no announced date for the next episode or season. It has a high IMDb audience rating of 8.5 (30,296 votes) and was very well received by critics. | H124: 2Seasons | I124: Hulu
A125: The Night Of | B125: 2016 | C125: 18+ | D125: 8.5 | E125: 85 | F125: Drama,Crime | G125: After a night of partying with a female stranger, a man wakes up to find her stabbed to death and is charged with her murder.The Night Of featuring Riz Ahmed and John Turturro has one or more episodes streaming with subscription on HBO MAX, streaming on HBO, and available for purchase on VUDU. It's a crime and drama show with 8 episodes over 1 season. The Night Of is no longer running and has no plans to air new episodes or seasons. It has a high IMDb audience rating of 8.5 (113,905 votes) and was very well received by critics. | H125: 1Season | I125: HBO MAX,HBO
A126: Buffy the Vampire Slayer | B126: 1997 | C126: 7+ | D126: 8.2 | E126: 85 | F126: Action & Adventure,Comedy | G126: Into every generation a slayer is born: one girl in all the world, a chosen one. She alone will wield the strength and skill to fight the vampires, demons, and the forces of darkness; to stop the spread of their evil and the swell of their number. She is the Slayer.Buffy the Vampire Slayer featuring Sarah Michelle Gellar and Alyson Hannigan has one or more episodes streaming with subscription on Hulu, available for purchase on iTunes, available for purchase on Google Play, and 4 others. It's an action & adventure and comedy show with 144 episodes over 7 seasons. Buffy the Vampire Slayer is no longer running and has no plans to air new episodes or seasons. It has a high IMDb audience rating of 8.2 (126,149 votes) and was well received by critics. | H126: 7Seasons | I126: Hulu
A127: White Collar | B127: 2009 | C127: 16+ | D127: 8.2 | E127: 85 | F127: Action & Adventure,Crime | G127: Neal Caffrey, a con man, forger and thief, is captured after a three-year game of cat and mouse with the FBI. With only months left serving a four-year sentence, he escapes to look for Kate, his girlfriend. Peter Burke, the FBI agent who initially captured Caffrey, finds and returns him to prison. This time, Caffrey proposes a deal with the FBI, as part of a work-release program. After some hesitation, Burke agrees, and thus begins this unconventional arrangement where Caffrey helps Burke apprehend white collar criminals.White Collar featuring Matt Bomer and Tim DeKay has one or more episodes streaming with subscription on Hulu, free on IMDb TV, available for purchase on iTunes, and 4 others. It's an action & adventure and comedy show with 81 episodes over 6 seasons. White Collar is no longer running and has no plans to air new episodes or seasons. It has a high IMDb audience rating of 8.2 (115,930 votes) and was very well received by critics. | H127: 6Seasons | I127: Free Services,Hulu
A128: Billions | B128: 2016 | C128: 18+ | D128: 8.4 | E128: 85 | F128: Drama,2016 | G128: A complex drama about power politics in the world of New York high finance. Shrewd, savvy U.S. Attorney Chuck Rhoades and the brilliant, ambitious hedge fund king Bobby "Axe" Axelrod are on an explosive collision course, with each using all of his considerable smarts, power and influence to outmaneuver the other. The stakes are in the billions in this timely, provocative series.Billions featuring Paul Giamatti and Damian Lewis has one or more episodes streaming on Showtime, free on Showtime FREEview, streaming with subscription on fuboTV, and 6 others. It's a drama show with 60 episodes over 5 seasons. Billions is still airing with no announced date for the next episode or season. It has a high IMDb audience rating of 8.4 (66,463 votes) and was well received by critics. | H128: 5Seasons | I128: Free Services,Showtime,fuboTV
A129: The West Wing | B129: 1999 | C129: 16+ | D129: 8.8 | E129: 85 | F129: Drama,1999 | G129: The West Wing provides a glimpse into presidential politics in the nation's capital as it tells the stories of the members of a fictional presidential administration. These interesting characters have humor and dedication that touches the heart while the politics that they discuss touch on everyday life.The West Wing featuring Martin Sheen and Allison Janney has one or more episodes streaming with subscription on Netflix, available for purchase on iTunes, available for purchase on Google Play, and 3 others. It's a drama show with 155 episodes over 7 seasons. The West Wing is no longer running and has no plans to air new episodes or seasons. It has a high IMDb audience rating of 8.8 (60,875 votes) and was well received by critics. | H129: 7Seasons | I129: Netflix
A130: Love, Death & Robots | B130: 2019 | C130: 18+ | D130: 8.5 | E130: 85 | F130: Animation,Science-Fiction | G130: Terrifying creatures, wicked surprises and dark comedy converge in this NSFW anthology of animated stories presented by Tim Miller and David Fincher.Love, Death & Robots has one or more episodes streaming with subscription on Netflix. It's an animation and comedy show with 18 episodes over 1 season. Love, Death & Robots is still airing with no announced date for the next episode or season. It has a high IMDb audience rating of 8.5 (89,025 votes) and was well received by critics. | H130: 1Season | I130: Netflix
A131: Legion | B131: 2017 | C131: 16+ | D131: 8.3 | E131: 85 | F131: Action & Adventure,Science-Fiction | G131: David Haller, AKA Legion, is a troubled young man who may be more than human. Diagnosed as schizophrenic, David has been in and out of psychiatric hospitals for years. But after a strange encounter with a fellow patient, he’s confronted with the possibility that the voices he hears and the visions he sees might be real.Legion featuring Dan Stevens and Rachel Keller has one or more episodes streaming with subscription on Hulu, available for purchase on iTunes, available for purchase on Google Play, and 3 others. It's an action & adventure and drama show with 27 episodes over 3 seasons. Legion is no longer running and has no plans to air new episodes or seasons. It has a high IMDb audience rating of 8.3 (80,602 votes) and was very well received by critics. | H131: 3 Seasons | I131: Hulu
A132: Ted Lasso | B132: 2020 | C132: 18+ | D132: 8.6 | E132: 85 | F132: Comedy,Drama | G132: Ted Lasso, an American football coach, moves to England when he’s hired to manage a soccer team—despite having no experience. With cynical players and a doubtful town, will he get them to see the Ted Lasso Way?Ted Lasso featuring Jason Sudeikis and Hannah Waddingham has one or more episodes streaming with subscription on Apple TV+. It's a comedy and drama show with 7 episodes over 1 season. Ted Lasso has a new episode airing on September 17th, 2020 (PDT). It has a high IMDb audience rating of 8.6 (5,651 votes) and was well received by critics. | H132: 1 Season | I132: Apple TV+
A133: Psych | B133: 2006 | C133: 7+ | D133: 8.3 | E133: 85 | F133: Comedy,Crime | G133: Thanks to his police officer father's efforts, Shawn Spencer spent his childhood developing a keen eye for detail (and a lasting dislike of his dad). Years later, Shawn's frequent tips to the police lead to him being falsely accused of a crime he solved. Now, Shawn has no choice but to use his abilities to perpetuate his cover story: psychic crime-solving powers, all the while dragging his best friend, his dad, and the police along for the ride.Psych featuring James Roday Rodriguez and Dulé Hill has one or more episodes streaming with subscription on Prime Video, free on IMDb TV, free on Peacock, and 4 others. It's a comedy and crime show with 122 episodes over 8 seasons. Psych is no longer running and has no plans to air new episodes or seasons. It has a high IMDb audience rating of 8.3 (83,014 votes) and was very well received by critics. | H133: 8 Seasons | I133: Free Services,Prime Video
A134: Marvel's Jessica Jones | B134: 2015 | C134: 18+ | D134: 7.9 | E134: 85 | F134: Action & Adventure,Crime | G134: After a tragic ending to her short-lived super hero stint, Jessica Jones is rebuilding her personal life and career as a detective who gets pulled into cases involving people with extraordinary abilities in New York City.Marvel's Jessica Jones featuring Krysten Ritter and Rachael Taylor has one or more episodes streaming with subscription on Netflix, available for purchase on iTunes, available for purchase on Google Play, and 3 others. It's an action & adventure and crime show with 39 episodes over 3 seasons. Marvel's Jessica Jones is no longer running and has no plans to air new episodes or seasons. It has a high IMDb audience rating of 7.9 (189,094 votes) and was well received by critics. | H134: 3Seasons | I134: Netflix
A135: Kingdom | B135: 2019 | C135: 18+ | D135: 8.4 | E135: 85 | F135: Action & Adventure,Drama | G135: In this zombie thriller set in Korea's medieval Joseon dynasty, a crown prince is sent on a suicide mission to investigate a mysterious outbreak.Kingdom featuring Ju Ji-hoon and Ryu Seung-ryong has one or more episodes streaming with subscription on Netflix. It's an action & adventure and drama show with 12 episodes over 2 seasons. Kingdom is still airing with no announced date for the next episode or season. It has a high IMDb audience rating of 8.4 (26,193 votes) and was very well received by critics. | H135: 2Seasons | I135: Netflix
... A200: Russian Doll | B200: 2019 | C200: 18+ | D200: 7.9 | E200: 83 | F200: Comedy,Drama | G200: Nadia keeps dying and reliving her 36th birthday party. She's trapped in a surreal time loop -- and staring down the barrel of her own mortality.Russian Doll featuring Natasha Lyonne and Greta Lee has one or more episodes streaming with subscription on Netflix. It's a comedy and drama show with 8 episodes over 1 season. Russian Doll is still airing with no announced date for the next episode or season. It has a high IMDb audience rating of 7.9 (61,986 votes) and was very well received by critics. | H200: 1Season | I200: Netflix

Sheet Formula&Function
A1: SECTION 1 – FORMULAS & FUNCTIONS | C1: Answer
A2: 1. Calculate the total number of series in the dataset. | C2: =COUNTA(All_Streaming_Shows!A:A)-1 -> 199
A3: 2. Find the highest IMDb Rating. | C3: =MAX(All_Streaming_Shows!D:D) -> 9.5
A4: 3. Find the lowest IMDb Rating. | C4: =MIN(All_Streaming_Shows!D:D) -> 7.3
A5: 4. Calculate the average IMDb Rating of all series. | C5: =AVERAGE(All_Streaming_Shows!D:D) -> 8.4487437
A6: 5. Count how many series were released after 2015. | C6: =COUNTIF(All_Streaming_Shows!B:B,">2015") -> 66
A7: 6. Count how many series have Content Rating = “18+”. | C7: =COUNTIF(All_Streaming_Shows!C:C,"18+") -> 106
A8: 7. Count how many series belong to the Drama genre. | C8: =COUNTIF(All_Streaming_Shows!F:F,"*Drama*") -> 116
A9: 8. Find how many series are available on Netflix. | C9: =COUNTIF(All_Streaming_Shows!I:I,All_Streaming_Shows!I2) -> 49

Sheet Conditional Function
A1: SECTION 2 – CONDITIONAL FUNCTIONS | C1: Answer
A2: 1. Count the number of series with IMDb Rating greater than 9. | C2: =COUNTIF(All_Streaming_Shows!D:D,">9") -> 13
A3: 2. Count how many series belong to the Comedy genre. | C3: =COUNTIF(All_Streaming_Shows!F:F,"*Comedy*") -> 64
A4: 3. Calculate the average IMDb Rating for series with Content Rating = 18+. | C4: =AVERAGEIFS(All_Streaming_Shows!D:D,All_Streaming_Shows!C:C,">18+") -> 8.564
A5: 4. Count the number of series released before 2010. | C5: =COUNTIF(All_Streaming_Shows!B:B,"<2010") -> 66
A6: 5. Find the total number of seasons for series streamed on Netflix. | C6: =COUNTIF(All_Streaming_Shows!I:I,"Netflix") -> 49
A7: 6. Count how many series are available on more than one streaming platform. | C7: =COUNTIF(All_Streaming_Shows!I:I,"*,*") -> 110
A8: 7. Calculate average IMDb Rating for Action & Adventure series. | C8: =AVERAGEIFS(All_Streaming_Shows!D:D,All_Streaming_Shows!F:F,"*Action & Adventure*") -> 8.438
A9: 8. Count how many series have more than 3 seasons. | C9: =COUNTIF(All_Streaming_Shows!H:H,">3*") -> 116

Sheet Vlookup
A1: SECTION 3 – VLOOKUP
A2: 1. Use VLOOKUP to return the IMDb Rating of a given series.
A3: 2. Retrieve the Year Released for a selected series using VLOOKUP.
A4: 3. Find the Content Rating of a series using VLOOKUP.
A5: 4. Return the Genre of a given series using VLOOKUP.
A6: 5. Fetch the Streaming Platform of a selected series using VLOOKUP.
A7: 6. Retrieve the Number of Seasons using VLOOKUP.
A11: Answer | B11: Answer 1. | C11: Answer 2. | D11: Answer 3. | E11: Answer 4. | F11: Answer 5. | G11: Answer 6.
A12: Series Title | B12: IMDB Rating | C12: Year Released | D12: Content Rating | E12: Genre | F12: Streaming Platform | G12: Number of Seasons
A13: Schitt's Creek | B13: =VLOOKUP(A13,series,4,0) -> 8.4 | C13: =VLOOKUP(A13,series,2,0) -> 2015 | D13: =VLOOKUP(A13,series,3,0) -> 16+ | E13: =VLOOKUP(A13,series,6,0) -> Comedy,2015 | F13: =VLOOKUP(A13,series,9,0) -> Free Services,Netflix,Prime Video | G13: =VLOOKUP(A13,series,8,0) -> 6 Seasons
A14: New Girl | B14: =VLOOKUP(A14,series,4,0) -> 7.7 | C14: =VLOOKUP(A14,series,2,0) -> 2011 | D14: =VLOOKUP(A14,series,3,0) -> 16+ | E14: =VLOOKUP(A14,series,6,0) -> Comedy,2011 | F14: =VLOOKUP(A14,series,9,0) -> Netflix,TBS | G14: =VLOOKUP(A14,series,8,0) -> 7 Seasons
A15: The Shield | B15: =VLOOKUP(A15,series,4,0) -> 8.7 | C15: =VLOOKUP(A15,series,2,0) -> 2002 | D15: =VLOOKUP(A15,series,3,0) -> 18+ | E15: =VLOOKUP(A15,series,6,0) -> Crime,Drama | F15: =VLOOKUP(A15,series,9,0) -> Hulu | G15: =VLOOKUP(A15,series,8,0) -> 7Seasons
A16: Line of Duty | B16: =VLOOKUP(A16,series,4,0) -> 8.7 | C16: =VLOOKUP(A16,series,2,0) -> 2012 | D16: =VLOOKUP(A16,series,3,0) -> 18+ | E16: =VLOOKUP(A16,series,6,0) -> Crime,Drama | F16: =VLOOKUP(A16,series,9,0) -> Hulu,AcornTV,AMC | G16: =VLOOKUP(A16,series,8,0) -> 5Seasons
A17: Bodyguard | B17: =VLOOKUP(A17,series,4,0) -> 8.1 | C17: =VLOOKUP(A17,series,2,0) -> 2018 | D17: =VLOOKUP(A17,series,3,0) -> 18+ | E17: =VLOOKUP(A17,series,6,0) -> Thriller,Crime | F17: =VLOOKUP(A17,series,9,0) -> Netflix | G17: =VLOOKUP(A17,series,8,0) -> 1Season

Sheet For Hlookup
A1: Series Title | B1: Breaking Bad | C1: Game of Thrones | D1: Rick and Morty | E1: Stranger Things | F1: The Boys | G1: Dark | H1: Chernobyl | I1: Sherlock | J1: Fargo | K1: Avatar: The Last Airbender | L1: Friends | M1: The Office | N1: Supernatural | O1: The Wire | P1: Better Call Saul | Q1: Attack on Titan | R1: Black Mirror | S1: Band of Brothers | T1: House | U1: Lucifer | V1: Money Heist | W1: Mr. Robot | X1: Peaky Blinders | Y1: Cobra Kai | Z1: The Simpsons
A2: Year Released | B2: 2008 | C2: 2011 | D2: 2013 | E2: 2016 | F2: 2019 | G2: 2017 | H2: 2019 | I2: 2010 | J2: 2014 | K2: 2005 | L2: 1994 | M2: 2005 | N2: 2005 | O2: 2002 | P2: 2015 | Q2: 2013 | R2: 2011 | S2: 2001 | T2: 2004 | U2: 2016 | V2: 2017 | W2: 2015 | X2: 2013 | Y2: 2018 | Z2: 1989
A3: Content Rating | B3: 18+ | C3: 18+ | D3: 18+ | E3: 16+ | F3: 18+ | G3: 16+ | H3: 18+ | I3: 16+ | J3: 18+ | K3: 7+ | L3: 16+ | M3: 16+ | N3: 16+ | O3: 18+ | P3: 18+ | Q3: 18+ | R3: 18+ | S3: 18+ | T3: 16+ | U3: 16+ | V3: 18+ | W3: 18+ | X3: 18+ | Y3: 16+ | Z3: 7+
A4: IMDB Rating | B4: 9.5 | C4: 9.3 | D4: 9.2 | E4: 8.8 | F4: 8.7 | G4: 8.8 | H4: 9.4 | I4: 9.1 | J4: 8.9 | K4: 9.2 | L4: 8.9 | M4: 8.9 | N4: 8.4 | O4: 9.3 | P4: 8.7 | Q4: 8.8 | R4: 8.8 | S4: 9.4 | T4: 8.7 | U4: 8.2 | V4: 8.4 | W4: 8.5 | X4: 8.8 | Y4: 8.8 | Z4: 8.7
A5: R Rating | B5: 100 | C5: 99 | D5: 97 | E5: 96 | F5: 95 | G5: 95 | H5: 95 | I5: 94 | J5: 94 | K5: 94 | L5: 94 | M5: 93 | N5: 93 | O5: 93 | P5: 92 | Q5: 92 | R5: 92 | S5: 92 | T5: 92 | U5: 92 | V5: 92 | W5: 92 | X5: 92 | Y5: 91 | Z5: 91
A6: Genre | B6: Crime,Drama | C6: Action & Adventure,Drama | D6: Animation,Comedy | E6: Drama,Fantasy | F6: Action & Adventure,Comedy | G6: Crime,Drama | H6: Drama,History | I6: Action & Adventure,Crime | J6: Crime,Drama | K6: Action & Adventure,Animation | L6: Comedy,Romance | M6: Comedy,2005 | N6: Drama,Fantasy | O6: Crime,Drama | P6: Comedy,Crime | Q6: Action & Adventure,Anime | R6: Drama,Science-Fiction | S6: Action & Adventure,Drama | T6: Drama,Mystery | U6: Fantasy,Crime | V6: Thriller,Action & Adventure | W6: Drama,Thriller | X6: Crime,Drama | Y6: Action & Adventure,Drama | Z6: Animation,Comedy
A7: Description | B7: When Walter White, a New Mexico chemistry teacher, is diagnosed with Stage III cancer and given a prognosis of only two years left to live. He becomes filled with a sense of fearlessness and an unrelenting desire to secure his family's financial future at any cost as he enters the dangerous world of drugs and crime.Breaking Bad featuring Bryan Cranston and Aaron Paul has one or more episodes streaming with subscription on Netflix, available for purchase on iTunes, available for purchase on Google Play, and 3 others. It's a crime and drama show with 62 episodes over 5 seasons. Breaking Bad is no longer running and has no plans to air new episodes or seasons. It has a very high IMDb audience rating of 9.5 (1,391,409 votes) and was very well received by critics. | C7: Seven noble families fight for control of the mythical land of Westeros. Friction between the houses leads to full-scale war. All while a very ancient evil awakens in the farthest north. Amidst the war, a neglected military order of misfits, the Night's Watch, is all that stands between the realms of men and icy horrors beyond.Game of Thrones featuring Emilia Clarke and Lena Headey has one or more episodes streaming with subscription on HBO MAX, streaming on HBO, available for purchase on iTunes, and 5 others. It's an action & adventure and drama show with 74 episodes over 8 seasons. Game of Thrones is no longer running and has no plans to air new episodes or seasons. It has a very high IMDb audience rating of 9.3 (1,704,731 votes) and was very well received by critics. | D7: Rick is a mentally-unbalanced but scientifically-gifted old man who has recently reconnected with his family. He spends most of his time involving his young grandson Morty in dangerous, outlandish adventures throughout space and alternate universes. Compounded with Morty's already unstable family life, these events cause Morty much distress at home and school.Rick and Morty featuring Justin Roiland and Chris Parnell has one or more episodes streaming with subscription on HBO MAX, streaming with subscription on Hulu, streaming via tv everywhere with Adult Swim (Via Cable/Satellite Provider), and 8 others. It's an action & adventure and animation show with 42 episodes over 4 seasons. Rick and Morty is still airing with no announced date for the next episode or season. It has a very high IMDb audience rating of 9.2 (354,057 votes) and was very well received by critics. | E7: When a young boy vanishes, a small town uncovers a mystery involving secret experiments, terrifying supernatural forces, and one strange little girl.Stranger Things featuring Winona Ryder and David Harbour has one or more episodes streaming with subscription on Netflix. It's an action & adventure and drama show with 25 episodes over 3 seasons. Stranger Things is still airing with no announced date for the next episode or season. It has a high IMDb audience rating of 8.8 (766,806 votes) and was very well received by critics. | F7: A group of vigilantes known informally as “The Boys” set out to take down corrupt superheroes with no more than blue-collar grit and a willingness to fight dirty.The Boys featuring Karl Urban and Jack Quaid has one or more episodes streaming with subscription on Prime Video, and available for purchase on VUDU. It's an action & adventure and comedy show with 12 episodes over 2 seasons. The Boys has a new episode airing on September 17th, 2020 (PDT). It has a high IMDb audience rating of 8.7 (170,705 votes) and was very well received by critics. | G7: A missing child causes four families to help each other for answers. What they could not imagine is that this mystery would be connected to innumerable other secrets of the small town.Dark has one or more episodes streaming with subscription on Netflix. It's a crime and drama show with 26 episodes over 3 seasons. Dark is no longer running and has no plans to air new episodes or seasons. It has a high IMDb audience rating of 8.8 (249,219 votes) and was very well received by critics. | H7: The true story of one of the worst man-made catastrophes in history: the catastrophic nuclear accident at Chernobyl. A tale of the brave men and women who sacrificed to save Europe from unimaginable disaster.Chernobyl featuring Jared Harris and Stellan Skarsgård has one or more episodes streaming with subscription on HBO MAX, streaming on HBO, available for purchase on Google Play, and 2 others. It's a drama and history show with 5 episodes over 1 season. Chernobyl is no longer running and has no plans to air new episodes or seasons. It has a very high IMDb audience rating of 9.4 (494,136 votes) and was very well received by critics. | I7: A modern update finds the famous sleuth and his doctor partner solving crime in 21st century London.Sherlock featuring Benedict Cumberbatch and Martin Freeman has one or more episodes streaming with subscription on Netflix, available for purchase on iTunes, available for purchase on Google Play, and 3 others. It's an action & adventure and crime show with 13 episodes over 4 seasons. Sherlock is no longer running and has no plans to air new episodes or seasons. It has a very high IMDb audience rating of 9.1 (778,486 votes) and was well received by critics. | J7: A close-knit anthology series dealing with stories involving malice, violence and murder based in and around Minnesota.Fargo featuring Ewan McGregor and Michael Stuhlbarg has one or more episodes streaming with subscription on Hulu, available for purchase on iTunes, available for purchase on Google Play, and 3 others. It's a comedy and crime show with 30 episodes over 3 seasons. Fargo is still airing with no announced date for the next episode or season. It has a high IMDb audience rating of 8.9 (309,584 votes) and was very well received by critics. | K7: In a war-torn world of elemental magic, a young boy reawakens to undertake a dangerous mystic quest to fulfill his destiny as the Avatar, and bring peace to the world.Avatar: The Last Airbender featuring Olivia Hack and Jennie Kwan has one or more episodes streaming with subscription on Netflix, streaming on CBS All Access, streaming with subscription on Hoopla, and 6 others. It's an action & adventure and animation show with 66 episodes over 3 seasons. Avatar: The Last Airbender is no longer running and has no plans to air new episodes or seasons. It has a very high IMDb audience rating of 9.2 (232,305 votes) and was very well received by critics. | L7: The misadventures of a group of friends as they navigate the pitfalls of work, life and love in Manhattan.Friends featuring Matthew Perry and Matt LeBlanc has one or more episodes streaming with subscription on HBO MAX, streaming with subscription on Hulu, streaming via tv everywhere with TBS, and 6 others. It's a comedy and drama show with 238 episodes over 10 seasons. Friends is no longer running and has no plans to air new episodes or seasons. It has a high IMDb audience rating of 8.9 (785,332 votes) and was well received by critics. | M7: The everyday lives of office employees in the Scranton, Pennsylvania branch of the fictional Dunder Mifflin Paper Company.The Office featuring Rainn Wilson and Jenna Fischer has one or more episodes streaming with subscription on Netflix, streaming via tv everywhere with Comedy Central (Via Cable/Satellite Provider), streaming with subscription on fuboTV, and 3 others. It's a comedy show with 224 episodes over 9 seasons. The Office is no longer running and has no plans to air new episodes or seasons. It has a high IMDb audience rating of 8.9 (378,896 votes) and was well received by critics. | N7: When they were boys, Sam and Dean Winchester lost their mother to a mysterious and demonic supernatural force. Subsequently, their father raised them to be soldiers. He taught them about the paranormal evil that lives in the dark corners and on the back roads of America ... and he taught them how to kill it. Now, the Winchester brothers crisscross the country in their '67 Chevy Impala, battling every kind of supernatural threat they encounter along the way.Supernatural featuring Jensen Ackles and Jared Padalecki has one or more episodes streaming with subscription on Netflix, streaming via tv everywhere with TNT, free on The CW, and 6 others. It's a drama and fantasy show with 322 episodes over 15 seasons. Supernatural has a new episode airing on October 8th, 2020 (PDT). It has a high IMDb audience rating of 8.4 (378,738 votes) and was very well received by critics. | O7: Told from the points of view of both the Baltimore homicide and narcotics detectives and their targets, the series captures a universe in which the national war on drugs has become a permanent, self-sustaining bureaucracy, and distinctions between good and evil are routinely obliterated.The Wire featuring Dominic West and Lance Reddick has one or more episodes streaming with subscription on HBO MAX, streaming on HBO, available for purchase on iTunes, and 5 others. It's a crime and drama show with 60 episodes over 5 seasons. The Wire is no longer running and has no plans to air new episodes or seasons. It has a very high IMDb audience rating of 9.3 (274,706 votes) and was very well received by critics. | P7: Six years before Saul Goodman meets Walter White. We meet him when the man who will become Saul Goodman is known as Jimmy McGill, a small-time lawyer searching for his destiny, and, more immediately, hustling to make ends meet. Working alongside, and, often, against Jimmy, is “fixer” Mike Ehrmantraut. The series tracks Jimmy’s transformation into Saul Goodman, the man who puts “criminal” in “criminal lawyer".Better Call Saul featuring Bob Odenkirk and Jonathan Banks has one or more episodes streaming with subscription on Netflix, available for purchase on iTunes, available for purchase on Google Play, and 3 others. It's a comedy and crime show with 50 episodes over 5 seasons. Better Call Saul is still airing with no announced date for the next episode or season. It has a high IMDb audience rating of 8.7 (305,414 votes) and was very well received by critics. | Q7: Several hundred years ago, humans were nearly exterminated by Titans. Titans are typically several stories tall, seem to have no intelligence, devour human beings and, worst of all, seem to do it for the pleasure rather than as a food source. A small percentage of humanity survived by walling themselves in a city protected by extremely high walls, even taller than the biggest Titans. Flash forward to the present and the city has not seen a Titan in over 100 years. Teenage boy Eren and his foster sister Mikasa witness something horrific as the city walls are destroyed by a Colossal Titan that appears out of thin air. As the smaller Titans flood the city, the two kids watch in horror as their mother is eaten alive. Eren vows that he will murder every single Titan and take revenge for all of mankind.Attack on Titan featuring Yuki Kaji and Marina Inoue has one or more episodes streaming with subscription on Netflix, streaming with subscription on Hulu, streaming with subscription on Crunchyroll, and 10 others. It's an action & adventure and animation show with 60 episodes over 3 seasons. Attack on Titan is still airing with no announced date for the next episode or season. It has a high IMDb audience rating of 8.8 (146,875 votes) and was very well received by critics. | R7: A contemporary British re-working of The Twilight Zone with stories that tap into the collective unease about our modern world. Over the last ten years, technology has transformed almost every aspect of our lives before we've had time to stop and question it. In every home; on every desk; in every palm - a plasma screen; a monitor; a smartphone - a black mirror of our 21st Century existence.Black Mirror has one or more episodes streaming with subscription on Netflix, and available for purchase on iTunes. It's a drama and fantasy show with 22 episodes over 5 seasons. Black Mirror is still airing with no announced date for the next episode or season. It has a high IMDb audience rating of 8.8 (417,642 votes) and was well received by critics. | S7: Drawn from interviews with survivors of Easy Company, as well as their journals and letters, Band of Brothers chronicles the experiences of these men from paratrooper training in Georgia through the end of the war. As an elite rifle company parachuting into Normandy early on D-Day morning, participants in the Battle of the Bulge, and witness to the horrors of war, the men of Easy knew extraordinary bravery and extraordinary fear - and became the stuff of legend. Based on Stephen E. Ambrose's acclaimed book of the same name.Band of Brothers featuring Damian Lewis and Donnie Wahlberg has one or more episodes streaming with subscription on HBO MAX, streaming on HBO, available for purchase on iTunes, and 5 others. It's an action & adventure and drama show with 10 episodes over 1 season. Band of Brothers is no longer running and has no plans to air new episodes or seasons. It has a very high IMDb audience rating of 9.4 (362,057 votes) and was very well received by critics. | T7: Dr. Gregory House, a drug-addicted, unconventional, misanthropic medical genius, leads a team of diagnosticians at the fictional Princeton–Plainsboro Teaching Hospital in New Jersey.House featuring Hugh Laurie and Omar Epps has one or more episodes streaming with subscription on Prime Video, streaming via tv everywhere with NBC (Via Cable/Satellite Provider), free on NBC, and 3 others. It's a comedy and drama show with 180 episodes over 8 seasons. House is no longer running and has no plans to air new episodes or seasons. It has a high IMDb audience rating of 8.7 (404,083 votes) and was very well received by critics. | U7: Bored and unhappy as the Lord of Hell, Lucifer Morningstar abandoned his throne and retired to Los Angeles, where he has teamed up with LAPD detective Chloe Decker to take down criminals. But the longer he's away from the underworld, the greater the threat that the worst of humanity could escape.Lucifer featuring Tom Ellis and Lauren German has one or more episodes streaming with subscription on Netflix, available for purchase on iTunes, available for purchase on Google Play, and 4 others. It's a comedy and crime show with 75 episodes over 5 seasons. Lucifer is still airing with no announced date for the next episode or season. It has a high IMDb audience rating of 8.2 (209,541 votes) and was well received by critics. | V7: To carry out the biggest heist in history, a mysterious man called The Professor recruits a band of eight robbers who have a single characteristic: none of them has anything to lose. Five months of seclusion - memorizing every step, every detail, every probability - culminate in eleven days locked up in the National Coinage and Stamp Factory of Spain, surrounded by police forces and with dozens of hostages in their power, to find out whether their suicide wager will lead to everything or nothing.Money Heist featuring Úrsula Corberó and Álvaro Morte has one or more episodes streaming with subscription on Netflix. It's an action & adventure and crime show with 38 episodes over 2 seasons. Money Heist is still airing with no announced date for the next episode or season. It has a high IMDb audience rating of 8.4 (269,489 votes) and was very well received by critics. | W7: A contemporary and culturally resonant drama about a young programmer, Elliot, who suffers from a debilitating anti-social disorder and decides that he can only connect to people by hacking them. He wields his skills as a weapon to protect the people that he cares about. Elliot will find himself in the intersection between a cybersecurity firm he works for and the underworld organizations that are recruiting him to bring down corporate America.Mr. Robot featuring Rami Malek and Christian Slater has one or more episodes streaming with subscription on Prime Video, streaming via tv everywhere with USA (Via Cable/Satellite Provider), streaming with subscription on fuboTV, and 5 others. It's a crime and drama show with 45 episodes over 4 seasons. Mr. Robot is no longer running and has no plans to air new episodes or seasons. It has a high IMDb audience rating of 8.5 (321,181 votes) and was very well received by critics. | X7: A gangster family epic set in 1919 Birmingham, England and centered on a gang who sew razor blades in the peaks of their caps, and their fierce boss Tommy Shelby, who means to move up in the world.Peaky Blinders featuring Cillian Murphy and Paul Anderson has one or more episodes streaming with subscription on Netflix, available for purchase on iTunes, available for purchase on Google Play, and 3 others. It's a crime and drama show with 30 episodes over 5 seasons. Peaky Blinders is still airing with no announced date for the next episode or season. It has a high IMDb audience rating of 8.8 (308,525 votes) and was very well received by critics. | Y7: This Karate Kid sequel series picks up 30 years after the events of the 1984 All Valley Karate Tournament and finds Johnny Lawrence on the hunt for redemption by reopening the infamous Cobra Kai karate dojo. This reignites his old rivalry with the successful Daniel LaRusso, who has been working to maintain the balance in his life without mentor Mr. Miyagi.Cobra Kai featuring Ralph Macchio and William Zabka has one or more episodes streaming with subscription on Netflix, streaming with subscription on YouTube Premium, free on YouTube Premium, and 5 others. It's an action & adventure and comedy show with 20 episodes over 2 seasons. Cobra Kai is still airing with no announced date for the next episode or season. It has a high IMDb audience rating of 8.8 (57,711 votes) and was very well received by critics. | Z7: Set in Springfield, the average American town, the show focuses on the antics and everyday adventures of the Simpson family; Homer, Marge, Bart, Lisa and Maggie, as well as a virtual cast of thousands. Since the beginning, the series has been a pop culture icon, attracting hundreds of celebrities to guest star. The show has also made name for itself in its fearless satirical take on politics, media and American life in general.The Simpsons featuring Dan Castellaneta and Julie Kavner has one or more episodes streaming with subscription on Hulu, streaming via tv everywhere with FX (Via Cable/Satellite Provider), streaming with subscription on Disney+, and 7 others. It's an animation and comedy show with 684 episodes over 31 seasons. The Simpsons has a new episode airing on September 27th, 2020 (PDT). It has a high IMDb audience rating of 8.7 (356,453 votes) and was well received by critics.
A8: No of Seasons | B8: 5Seasons | C8: 8Seasons | D8: 4Seasons | E8: 3Seasons | F8: 2Seasons | G8: 3Seasons | H8: 1Season | I8: 4Seasons | J8: 3Seasons | K8: 3Seasons | L8: 10Seasons | M8: 9Seasons | N8: 15 Seasons | O8: 5Seasons | P8: 5Seasons | Q8: 3Seasons | R8: 5Seasons | S8: 1 Season | T8: 8Seasons | U8: 5Seasons | V8: 2Seasons | W8: 4Seasons | X8: 5 Seasons | Y8: 2Seasons | Z8: 31 Seasons
A9: Streaming Platform | B9: Netflix | C9: HBO MAX,HBO | D9: Free Services,HBO MAX,Hulu | E9: Netflix | F9: Prime Video | G9: Netflix | H9: HBO MAX,HBO | I9: Netflix | J9: Hulu | K9: Netflix,CBS All Access,Hoopla | L9: HBO MAX,Hulu,TBS | M9: Netflix,Comedy Central,fuboTV | N9: Free Services,Netflix,TNT | O9: HBO MAX,HBO | P9: Netflix | Q9: Free Services,Netflix,Hulu | R9: Netflix | S9: HBO MAX,HBO | T9: Free Services,Prime Video,NBC | U9: Netflix | V9: Netflix | W9: Prime Video,USA,fuboTV | X9: Netflix | Y9: Free Services,Netflix,YouTube Premium | Z9: Free Services,Hulu,FX

Sheet Hlookup
A1: SECTION 4 – HLOOKUP
A2: (Assume the data is arranged horizontally for practice)
A3: 1. Use HLOOKUP to retrieve the IMDb Rating of a selected series.
A4: 2. Retrieve the Year Released using HLOOKUP.
A5: 3. Fetch the Content Rating using HLOOKUP.
A6: 4. Return the Number of Seasons using HLOOKUP.
A7: 5. Find the highest rating value from the HLOOKUP result row.
A10: Answer | B10: Series Title | C10: Breaking Bad | D10: Game of Thrones | E10: Rick and Morty | F10: Stranger Things | G10: The Boys
A11: Answer 1. | B11: IMDB Rating | C11: =HLOOKUP(C10,seriesH,4,0) -> 9.5 | D11: =HLOOKUP(D10,seriesH,4,0) -> 9.3 | E11: =HLOOKUP(E10,seriesH,4,0) -> 9.2 | F11: =HLOOKUP(F10,seriesH,4,0) -> 8.8 | G11: =HLOOKUP(G10,seriesH,4,0) -> 8.7
A12: Answer 2. | B12: Year Released | C12: =HLOOKUP(C10,seriesH,2,0) -> 2008 | D12: =HLOOKUP(D10,seriesH,2,0) -> 2011 | E12: =HLOOKUP(E10,seriesH,2,0) -> 2013 | F12: =HLOOKUP(F10,seriesH,2,0) -> 2016 | G12: =HLOOKUP(G10,seriesH,2,0) -> 2019
A13: Answer 3. | B13: Content Rating | C13: =HLOOKUP(C10,seriesH,3,0) -> 18+ | D13: =HLOOKUP(D10,seriesH,3,0) -> 18+ | E13: =HLOOKUP(E10,seriesH,3,0) -> 18+ | F13: =HLOOKUP(F10,seriesH,3,0) -> 16+ | G13: =HLOOKUP(G10,seriesH,3,0) -> 18+
A14: Answer 4. | B14: Genre | C14: =HLOOKUP(C10,seriesH,6,0) -> Crime,Drama | D14: =HLOOKUP(D10,seriesH,6,0) -> Action & Adventure,Drama | E14: =HLOOKUP(E10,seriesH,6,0) -> Animation,Comedy | F14: =HLOOKUP(F10,seriesH,6,0) -> Drama,Fantasy | G14: =HLOOKUP(G10,seriesH,6,0) -> Action & Adventure,Comedy
A15: Answer 5. | B15: Streaming Platform | C15: =HLOOKUP(C10,seriesH,9,0) -> Netflix | D15: =HLOOKUP(D10,seriesH,9,0) -> HBO MAX,HBO | E15: =HLOOKUP(E10,seriesH,9,0) -> Free Services,HBO MAX,Hulu | F15: =HLOOKUP(F10,seriesH,9,0) -> Netflix | G15: =HLOOKUP(G10,seriesH,9,0) -> Prime Video
A16: Answer 6. | B16: Number of Seasons | C16: =HLOOKUP(C10,seriesH,8,0) -> 5Seasons | D16: =HLOOKUP(D10,seriesH,8,0) -> 8Seasons | E16: =HLOOKUP(E10,seriesH,8,0) -> 4Seasons | F16: =HLOOKUP(F10,seriesH,8,0) -> 3Seasons | G16: =HLOOKUP(G10,seriesH,8,0) -> 2Seasons

Sheet Index+Match
A1: SECTION 5 – INDEX + MATCH
A2: 1. Retrieve the IMDb Rating for a given series using INDEX + MATCH.
A3: 2. Fetch the Streaming Platform of a selected series using INDEX + MATCH.
A4: 3. Return the Genre of a series using INDEX + MATCH.
A5: 4. Find the Year Released using INDEX + MATCH.
A6: 5. Fetch the Number of Seasons using INDEX + MATCH.
A7: 6. Retrieve the Content Rating using INDEX + MATCH.
A10: Answer | B10: Answer 1. | C10: Answer 2. | D10: Answer 3. | E10: Answer 4. | F10: Answer 5. | G10: Answer 6.
A11: Series Title | B11: IMDB Rating | C11: Streaming Platform | D11: Genre | E11: Year Released | F11: No of Seasons | G11: Content Rating
A12: The Flash | B12: =INDEX(series,MATCH($A12,All_Streaming_Shows!$A$2:$A$900,0),MATCH('Index+Match'!B$11,All_Streaming_Shows!$A$1:$I$1,0)) -> 8.6 | C12: =INDEX(series,MATCH($A12,All_Streaming_Shows!$A$2:$A$900,0),MATCH('Index+Match'!C$11,All_Streaming_Shows!$A$1:$I$1,0)) -> Free Services,Hulu,BBC America | D12: =INDEX(series,MATCH($A12,All_Streaming_Shows!$A$2:$A$900,0),MATCH('Index+Match'!D$11,All_Streaming_Shows!$A$1:$I$1,0)) -> Drama,Science-Fiction | E12: =INDEX(series,MATCH($A12,All_Streaming_Shows!$A$2:$A$900,0),MATCH('Index+Match'!E$11,All_Streaming_Shows!$A$1:$I$1,0)) -> 1993 | F12: =INDEX(series,MATCH($A12,All_Streaming_Shows!$A$2:$A$900,0),MATCH('Index+Match'!F$11,All_Streaming_Shows!$A$1:$I$1,0)) -> 11Seasons | G12: =INDEX(series,MATCH($A12,All_Streaming_Shows!$A$2:$A$900,0),MATCH('Index+Match'!G$11,All_Streaming_Shows!$A$1:$I$1,0)) -> 16+
A13: Justified | B13: =INDEX(series,MATCH($A13,All_Streaming_Shows!$A$2:$A$900,0),MATCH('Index+Match'!B$11,All_Streaming_Shows!$A$1:$I$1,0)) -> 7.7 | C13: =INDEX(series,MATCH($A13,All_Streaming_Shows!$A$2:$A$900,0),MATCH('Index+Match'!C$11,All_Streaming_Shows!$A$1:$I$1,0)) -> Free Services,Netflix | D13: =INDEX(series,MATCH($A13,All_Streaming_Shows!$A$2:$A$900,0),MATCH('Index+Match'!D$11,All_Streaming_Shows!$A$1:$I$1,0)) -> Drama,Action & Adventure | E13: =INDEX(series,MATCH($A13,All_Streaming_Shows!$A$2:$A$900,0),MATCH('Index+Match'!E$11,All_Streaming_Shows!$A$1:$I$1,0)) -> 2014 | F13: =INDEX(series,MATCH($A13,All_Streaming_Shows!$A$2:$A$900,0),MATCH('Index+Match'!F$11,All_Streaming_Shows!$A$1:$I$1,0)) -> 6Seasons | G13: =INDEX(series,MATCH($A13,All_Streaming_Shows!$A$2:$A$900,0),MATCH('Index+Match'!G$11,All_Streaming_Shows!$A$1:$I$1,0)) -> 7+
A14: The Americans | B14: =INDEX(series,MATCH($A14,All_Streaming_Shows!$A$2:$A$900,0),MATCH('Index+Match'!B$11,All_Streaming_Shows!$A$1:$I$1,0)) -> 8.6 | C14: =INDEX(series,MATCH($A14,All_Streaming_Shows!$A$2:$A$900,0),MATCH('Index+Match'!C$11,All_Streaming_Shows!$A$1:$I$1,0)) -> Hulu | D14: =INDEX(series,MATCH($A14,All_Streaming_Shows!$A$2:$A$900,0),MATCH('Index+Match'!D$11,All_Streaming_Shows!$A$1:$I$1,0)) -> Action & Adventure,Crime | E14: =INDEX(series,MATCH($A14,All_Streaming_Shows!$A$2:$A$900,0),MATCH('Index+Match'!E$11,All_Streaming_Shows!$A$1:$I$1,0)) -> 2010 | F14: =INDEX(series,MATCH($A14,All_Streaming_Shows!$A$2:$A$900,0),MATCH('Index+Match'!F$11,All_Streaming_Shows!$A$1:$I$1,0)) -> 6 Seasons | G14: =INDEX(series,MATCH($A14,All_Streaming_Shows!$A$2:$A$900,0),MATCH('Index+Match'!G$11,All_Streaming_Shows!$A$1:$I$1,0)) -> 18+
A15: This Is Us | B15: =INDEX(series,MATCH($A15,All_Streaming_Shows!$A$2:$A$900,0),MATCH('Index+Match'!B$11,All_Streaming_Shows!$A$1:$I$1,0)) -> 8.4 | C15: =INDEX(series,MATCH($A15,All_Streaming_Shows!$A$2:$A$900,0),MATCH('Index+Match'!C$11,All_Streaming_Shows!$A$1:$I$1,0)) -> Prime Video | D15: =INDEX(series,MATCH($A15,All_Streaming_Shows!$A$2:$A$900,0),MATCH('Index+Match'!D$11,All_Streaming_Shows!$A$1:$I$1,0)) -> Drama,Crime | E15: =INDEX(series,MATCH($A15,All_Streaming_Shows!$A$2:$A$900,0),MATCH('Index+Match'!E$11,All_Streaming_Shows!$A$1:$I$1,0)) -> 2013 | F15: =INDEX(series,MATCH($A15,All_Streaming_Shows!$A$2:$A$900,0),MATCH('Index+Match'!F$11,All_Streaming_Shows!$A$1:$I$1,0)) -> 6Seasons | G15: =INDEX(series,MATCH($A15,All_Streaming_Shows!$A$2:$A$900,0),MATCH('Index+Match'!G$11,All_Streaming_Shows!$A$1:$I$1,0)) -> 18+
A16: Adventure Time | B16: =INDEX(series,MATCH($A16,All_Streaming_Shows!$A$2:$A$900,0),MATCH('Index+Match'!B$11,All_Streaming_Shows!$A$1:$I$1,0)) -> 8.7 | C16: =INDEX(series,MATCH($A16,All_Streaming_Shows!$A$2:$A$900,0),MATCH('Index+Match'!C$11,All_Streaming_Shows!$A$1:$I$1,0)) -> Free Services,Hulu,NBC | D16: =INDEX(series,MATCH($A16,All_Streaming_Shows!$A$2:$A$900,0),MATCH('Index+Match'!D$11,All_Streaming_Shows!$A$1:$I$1,0)) -> Drama,Comedy | E16: =INDEX(series,MATCH($A16,All_Streaming_Shows!$A$2:$A$900,0),MATCH('Index+Match'!E$11,All_Streaming_Shows!$A$1:$I$1,0)) -> 2016 | F16: =INDEX(series,MATCH($A16,All_Streaming_Shows!$A$2:$A$900,0),MATCH('Index+Match'!F$11,All_Streaming_Shows!$A$1:$I$1,0)) -> 4 Seasons | G16: =INDEX(series,MATCH($A16,All_Streaming_Shows!$A$2:$A$900,0),MATCH('Index+Match'!G$11,All_Streaming_Shows!$A$1:$I$1,0)) -> 16+
A17: BoJack Horseman | B17: =INDEX(series,MATCH($A17,All_Streaming_Shows!$A$2:$A$900,0),MATCH('Index+Match'!B$11,All_Streaming_Shows!$A$1:$I$1,0)) -> 8.6 | C17: =INDEX(series,MATCH($A17,All_Streaming_Shows!$A$2:$A$900,0),MATCH('Index+Match'!C$11,All_Streaming_Shows!$A$1:$I$1,0)) -> Free Services,HBO MAX,Hulu | D17: =INDEX(series,MATCH($A17,All_Streaming_Shows!$A$2:$A$900,0),MATCH('Index+Match'!D$11,All_Streaming_Shows!$A$1:$I$1,0)) -> Action & Adventure,Fantasy | E17: =INDEX(series,MATCH($A17,All_Streaming_Shows!$A$2:$A$900,0),MATCH('Index+Match'!E$11,All_Streaming_Shows!$A$1:$I$1,0)) -> 2010 | F17: =INDEX(series,MATCH($A17,All_Streaming_Shows!$A$2:$A$900,0),MATCH('Index+Match'!F$11,All_Streaming_Shows!$A$1:$I$1,0)) -> 11Seasons | G17: =INDEX(series,MATCH($A17,All_Streaming_Shows!$A$2:$A$900,0),MATCH('Index+Match'!G$11,All_Streaming_Shows!$A$1:$I$1,0)) -> 7+
A18: The Marvelous Mrs. Maisel | B18: =INDEX(series,MATCH($A18,All_Streaming_Shows!$A$2:$A$900,0),MATCH('Index+Match'!B$11,All_Streaming_Shows!$A$1:$I$1,0)) -> 8.7 | C18: =INDEX(series,MATCH($A18,All_Streaming_Shows!$A$2:$A$900,0),MATCH('Index+Match'!C$11,All_Streaming_Shows!$A$1:$I$1,0)) -> Netflix | D18: =INDEX(series,MATCH($A18,All_Streaming_Shows!$A$2:$A$900,0),MATCH('Index+Match'!D$11,All_Streaming_Shows!$A$1:$I$1,0)) -> Animation,Comedy | E18: =INDEX(series,MATCH($A18,All_Streaming_Shows!$A$2:$A$900,0),MATCH('Index+Match'!E$11,All_Streaming_Shows!$A$1:$I$1,0)) -> 2014 | F18: =INDEX(series,MATCH($A18,All_Streaming_Shows!$A$2:$A$900,0),MATCH('Index+Match'!F$11,All_Streaming_Shows!$A$1:$I$1,0)) -> 6Seasons | G18: =INDEX(series,MATCH($A18,All_Streaming_Shows!$A$2:$A$900,0),MATCH('Index+Match'!G$11,All_Streaming_Shows!$A$1:$I$1,0)) -> 18+
A19: The End of the F***ing World | B19: =INDEX(series,MATCH($A19,All_Streaming_Shows!$A$2:$A$900,0),MATCH('Index+Match'!B$11,All_Streaming_Shows!$A$1:$I$1,0)) -> 8.7 | C19: =INDEX(series,MATCH($A19,All_Streaming_Shows!$A$2:$A$900,0),MATCH('Index+Match'!C$11,All_Streaming_Shows!$A$1:$I$1,0)) -> Prime Video | D19: =INDEX(series,MATCH($A19,All_Streaming_Shows!$A$2:$A$900,0),MATCH('Index+Match'!D$11,All_Streaming_Shows!$A$1:$I$1,0)) -> Comedy,Stand-up & Talk | E19: =INDEX(series,MATCH($A19,All_Streaming_Shows!$A$2:$A$900,0),MATCH('Index+Match'!E$11,All_Streaming_Shows!$A$1:$I$1,0)) -> 2017 | F19: =INDEX(series,MATCH($A19,All_Streaming_Shows!$A$2:$A$900,0),MATCH('Index+Match'!F$11,All_Streaming_Shows!$A$1:$I$1,0)) -> 3Seasons | G19: =INDEX(series,MATCH($A19,All_Streaming_Shows!$A$2:$A$900,0),MATCH('Index+Match'!G$11,All_Streaming_Shows!$A$1:$I$1,0)) -> 18+
A20: Big Little Lies | B20: =INDEX(series,MATCH($A20,All_Streaming_Shows!$A$2:$A$900,0),MATCH('Index+Match'!B$11,All_Streaming_Shows!$A$1:$I$1,0)) -> 8.1 | C20: =INDEX(series,MATCH($A20,All_Streaming_Shows!$A$2:$A$900,0),MATCH('Index+Match'!C$11,All_Streaming_Shows!$A$1:$I$1,0)) -> Netflix | D20: =INDEX(series,MATCH($A20,All_Streaming_Shows!$A$2:$A$900,0),MATCH('Index+Match'!D$11,All_Streaming_Shows!$A$1:$I$1,0)) -> Action & Adventure,Comedy | E20: =INDEX(series,MATCH($A20,All_Streaming_Shows!$A$2:$A$900,0),MATCH('Index+Match'!E$11,All_Streaming_Shows!$A$1:$I$1,0)) -> 2017 | F20: =INDEX(series,MATCH($A20,All_Streaming_Shows!$A$2:$A$900,0),MATCH('Index+Match'!F$11,All_Streaming_Shows!$A$1:$I$1,0)) -> 2 Seasons | G20: =INDEX(series,MATCH($A20,All_Streaming_Shows!$A$2:$A$900,0),MATCH('Index+Match'!G$11,All_Streaming_Shows!$A$1:$I$1,0)) -> 18+
A21: Luther | B21: =INDEX(series,MATCH($A21,All_Streaming_Shows!$A$2:$A$900,0),MATCH('Index+Match'!B$11,All_Streaming_Shows!$A$1:$I$1,0)) -> 8.5 | C21: =INDEX(series,MATCH($A21,All_Streaming_Shows!$A$2:$A$900,0),MATCH('Index+Match'!C$11,All_Streaming_Shows!$A$1:$I$1,0)) -> HBO MAX,HBO | D21: =INDEX(series,MATCH($A21,All_Streaming_Shows!$A$2:$A$900,0),MATCH('Index+Match'!D$11,All_Streaming_Shows!$A$1:$I$1,0)) -> Crime,Drama | E21: =INDEX(series,MATCH($A21,All_Streaming_Shows!$A$2:$A$900,0),MATCH('Index+Match'!E$11,All_Streaming_Shows!$A$1:$I$1,0)) -> 2017 | F21: =INDEX(series,MATCH($A21,All_Streaming_Shows!$A$2:$A$900,0),MATCH('Index+Match'!F$11,All_Streaming_Shows!$A$1:$I$1,0)) -> 2Seasons | G21: =INDEX(series,MATCH($A21,All_Streaming_Shows!$A$2:$A$900,0),MATCH('Index+Match'!G$11,All_Streaming_Shows!$A$1:$I$1,0)) -> 18+
A22: Curb Your Enthusiasm | B22: =INDEX(series,MATCH($A22,All_Streaming_Shows!$A$2:$A$900,0),MATCH('Index+Match'!B$11,All_Streaming_Shows!$A$1:$I$1,0)) -> 8.5 | C22: =INDEX(series,MATCH($A22,All_Streaming_Shows!$A$2:$A$900,0),MATCH('Index+Match'!C$11,All_Streaming_Shows!$A$1:$I$1,0)) -> HBO MAX,Prime Video,Starz | D22: =INDEX(series,MATCH($A22,All_Streaming_Shows!$A$2:$A$900,0),MATCH('Index+Match'!D$11,All_Streaming_Shows!$A$1:$I$1,0)) -> Crime,Drama | E22: =INDEX(series,MATCH($A22,All_Streaming_Shows!$A$2:$A$900,0),MATCH('Index+Match'!E$11,All_Streaming_Shows!$A$1:$I$1,0)) -> 2010 | F22: =INDEX(series,MATCH($A22,All_Streaming_Shows!$A$2:$A$900,0),MATCH('Index+Match'!F$11,All_Streaming_Shows!$A$1:$I$1,0)) -> 5Seasons | G22: =INDEX(series,MATCH($A22,All_Streaming_Shows!$A$2:$A$900,0),MATCH('Index+Match'!G$11,All_Streaming_Shows!$A$1:$I$1,0)) -> 18+

Sheet Conditional Formatting
A1: SECTION 6 – CONDITIONAL FORMATTING
A2: 1. Highlight series with IMDb Rating above 9.
A3: 2. Highlight series released before 2010.
A4: 3. Apply data bars to the IMDb Rating column.
A5: 4. Highlight series with more than 4 seasons.
